<?xml version="1.0" encoding="utf-8"?>
<!-- Unitree G1 Humanoid - Control URDF (legs only, upper body fixed) -->
<!-- Auto-generated from github.com/unitreerobotics/unitree_ros g1_29dof -->
<robot name="g1_description">
  <link name="dummy_link">
  </link>
  <link name="pelvis">
    <inertial>
      <origin xyz="0 0 -0.07605" rpy="0 0 0"/>
      <mass value="3.813"/>
      <inertia ixx="0.010549" ixy="0" ixz="0" iyy="0.0093089" iyz="0" izz="0.0079184"/>
    </inertial>
    <visual>
      <origin xyz="0 0 0" rpy="0 0 0"/>
      <geometry>
        <mesh filename="package://humanoid_legged_description/meshes/pelvis.STL"/>
      </geometry>
      <material name="dark_grey">
        <color rgba="0.92 0.92 0.92 1"/>
      </material>
    </visual>
    <collision>
      <origin xyz="0 0 -0.07" rpy="0 0 0"/>
      <geometry>
        <box size="0.15 0.2 0.15"/>
      </geometry>
    </collision>
  </link>
  <joint name="dummy_to_pelvis" type="fixed">
    <parent link="dummy_link"/>
    <child link="pelvis"/>
    <origin rpy="0 0 0" xyz="0 0 0"/>
  </joint>

  <!-- Pelvis contour (covers hip connection area) -->
  <link name="pelvis_contour_link">
    <visual>
      <origin xyz="0 0 0" rpy="0 0 0"/>
      <geometry>
        <mesh filename="package://humanoid_legged_description/meshes/pelvis_contour_link.STL"/>
      </geometry>
      <material name="white">
        <color rgba="0.92 0.92 0.92 1"/>
      </material>
    </visual>
  </link>
  <joint name="pelvis_contour_joint" type="fixed">
    <origin xyz="0 0 0" rpy="0 0 0"/>
    <parent link="pelvis"/>
    <child link="pelvis_contour_link"/>
  </joint>

  <!-- Waist support (covers waist connection area) -->
  <link name="waist_support_link">
    <visual>
      <origin xyz="0 0 0" rpy="0 0 0"/>
      <geometry>
        <mesh filename="package://humanoid_legged_description/meshes/waist_support_link.STL"/>
      </geometry>
      <material name="light_grey">
        <color rgba="0.7 0.7 0.7 1"/>
      </material>
    </visual>
  </link>
  <joint name="waist_support_joint" type="fixed">
    <origin xyz="0 0 0" rpy="0 0 0"/>
    <parent link="pelvis"/>
    <child link="waist_support_link"/>
  </joint>

  <!-- ============== LEFT LEG ============== -->
  <link name="left_hip_pitch_link">
    <inertial>
      <origin xyz="0.002741 0.047791 -0.02606" rpy="0 0 0"/>
      <mass value="1.35"/>
      <inertia ixx="0.00181517" ixy="0" ixz="0" iyy="0.00153422" iyz="0" izz="0.00116212"/>
    </inertial>
    <visual>
      <origin xyz="0 0 0" rpy="0 0 0"/>
      <geometry>
        <mesh filename="package://humanoid_legged_description/meshes/left_hip_pitch_link.STL"/>
      </geometry>
      <material name="silver">
        <color rgba="0.45 0.45 0.5 1"/>
      </material>
    </visual>
  </link>
  <joint name="left_hip_pitch_joint" type="revolute">
    <origin xyz="0 0.064452 -0.1027" rpy="0 0 0"/>
    <parent link="pelvis"/>
    <child link="left_hip_pitch_link"/>
    <axis xyz="0 1 0"/>
    <limit lower="-2.5307" upper="2.8798" effort="88" velocity="32"/>
  </joint>

  <link name="left_hip_roll_link">
    <inertial>
      <origin xyz="0.029812 -0.001045 -0.087934" rpy="0 0 0"/>
      <mass value="1.52"/>
      <inertia ixx="0.00254986" ixy="0" ixz="0" iyy="0.00241169" iyz="0" izz="0.00148755"/>
    </inertial>
    <visual>
      <origin xyz="0 0 0" rpy="0 0 0"/>
      <geometry>
        <mesh filename="package://humanoid_legged_description/meshes/left_hip_roll_link.STL"/>
      </geometry>
      <material name="auto">
        <color rgba="0.7 0.7 0.7 1"/>
      </material>
    </visual>
  </link>
  <joint name="left_hip_roll_joint" type="revolute">
    <origin xyz="0 0.052 -0.030465" rpy="0 -0.1749 0"/>
    <parent link="left_hip_pitch_link"/>
    <child link="left_hip_roll_link"/>
    <axis xyz="1 0 0"/>
    <limit lower="-0.5236" upper="2.9671" effort="88" velocity="32"/>
  </joint>

  <link name="left_hip_yaw_link">
    <inertial>
      <origin xyz="-0.057709 -0.010981 -0.15078" rpy="0 0 0"/>
      <mass value="1.702"/>
      <inertia ixx="0.00776166" ixy="0" ixz="0" iyy="0.00717575" iyz="0" izz="0.00160139"/>
    </inertial>
    <visual>
      <origin xyz="0 0 0" rpy="0 0 0"/>
      <geometry>
        <mesh filename="package://humanoid_legged_description/meshes/left_hip_yaw_link.STL"/>
      </geometry>
      <material name="auto">
        <color rgba="0.7 0.7 0.7 1"/>
      </material>
    </visual>
  </link>
  <joint name="left_hip_yaw_joint" type="revolute">
    <origin xyz="0.025001 0 -0.12412" rpy="0 0 0"/>
    <parent link="left_hip_roll_link"/>
    <child link="left_hip_yaw_link"/>
    <axis xyz="0 0 1"/>
    <limit lower="-2.7576" upper="2.7576" effort="88" velocity="32"/>
  </joint>

  <link name="left_knee_link">
    <inertial>
      <origin xyz="0.005457 0.003964 -0.12074" rpy="0 0 0"/>
      <mass value="1.932"/>
      <inertia ixx="0.0113804" ixy="0" ixz="0" iyy="0.0112778" iyz="0" izz="0.00146458"/>
    </inertial>
    <visual>
      <origin xyz="0 0 0" rpy="0 0 0"/>
      <geometry>
        <mesh filename="package://humanoid_legged_description/meshes/left_knee_link.STL"/>
      </geometry>
      <material name="auto">
        <color rgba="0.7 0.7 0.7 1"/>
      </material>
    </visual>
  </link>
  <joint name="left_knee_joint" type="revolute">
    <origin xyz="-0.078273 0.0021489 -0.17734" rpy="0 0.1749 0"/>
    <parent link="left_hip_yaw_link"/>
    <child link="left_knee_link"/>
    <axis xyz="0 1 0"/>
    <limit lower="-0.087267" upper="2.8798" effort="139" velocity="20"/>
  </joint>

  <link name="left_ankle_pitch_link">
    <inertial>
      <origin xyz="-0.007269 0 0.011137" rpy="0 0 0"/>
      <mass value="0.074"/>
      <inertia ixx="1.89e-05" ixy="0" ixz="0" iyy="1.40805e-05" iyz="0" izz="6.9195e-06"/>
    </inertial>
    <visual>
      <origin xyz="0 0 0" rpy="0 0 0"/>
      <geometry>
        <mesh filename="package://humanoid_legged_description/meshes/left_ankle_pitch_link.STL"/>
      </geometry>
      <material name="auto">
        <color rgba="0.7 0.7 0.7 1"/>
      </material>
    </visual>
  </link>
  <joint name="left_ankle_pitch_joint" type="revolute">
    <origin xyz="0 -9.4445e-05 -0.30001" rpy="0 0 0"/>
    <parent link="left_knee_link"/>
    <child link="left_ankle_pitch_link"/>
    <axis xyz="0 1 0"/>
    <limit lower="-0.87267" upper="0.5236" effort="50" velocity="30"/>
  </joint>

  <link name="left_ankle_roll_link">
    <inertial>
      <origin xyz="0.026505 0 -0.016425" rpy="0 0 0"/>
      <mass value="0.608"/>
      <inertia ixx="0.00167218" ixy="0" ixz="0" iyy="0.0016161" iyz="0" izz="0.000217621"/>
    </inertial>
    <visual>
      <origin xyz="0 0 0" rpy="0 0 0"/>
      <geometry>
        <mesh filename="package://humanoid_legged_description/meshes/left_ankle_roll_link.STL"/>
      </geometry>
      <material name="dark_grey">
        <color rgba="0.35 0.35 0.38 1"/>
      </material>
    </visual>
    <collision>
      <origin xyz="0.035 0 -0.03" rpy="0 0 0"/>
      <geometry>
        <box size="0.18 0.08 0.01"/>
      </geometry>
    </collision>
  </link>
  <joint name="left_ankle_roll_joint" type="revolute">
    <origin xyz="0 0 -0.017558" rpy="0 0 0"/>
    <parent link="left_ankle_pitch_link"/>
    <child link="left_ankle_roll_link"/>
    <axis xyz="1 0 0"/>
    <limit lower="-0.2618" upper="0.2618" effort="50" velocity="30"/>
  </joint>

  <!-- Left foot contact frames -->
  <link name="l_foot_toe"></link>
  <joint name="l_foot_toe_joint" type="fixed">
    <origin xyz="0.12 0 -0.03" rpy="0 0 0"/>
    <parent link="left_ankle_roll_link"/>
    <child link="l_foot_toe"/>
  </joint>
  <link name="l_foot_heel"></link>
  <joint name="l_foot_heel_joint" type="fixed">
    <origin xyz="-0.05 0 -0.03" rpy="0 0 0"/>
    <parent link="left_ankle_roll_link"/>
    <child link="l_foot_heel"/>
  </joint>

  <!-- ============== RIGHT LEG ============== -->
  <link name="right_hip_pitch_link">
    <inertial>
      <origin xyz="0.002741 -0.047791 -0.02606" rpy="0 0 0"/>
      <mass value="1.35"/>
      <inertia ixx="0.00181517" ixy="0" ixz="0" iyy="0.00153422" iyz="0" izz="0.00116212"/>
    </inertial>
    <visual>
      <origin xyz="0 0 0" rpy="0 0 0"/>
      <geometry>
        <mesh filename="package://humanoid_legged_description/meshes/right_hip_pitch_link.STL"/>
      </geometry>
      <material name="silver">
        <color rgba="0.45 0.45 0.5 1"/>
      </material>
    </visual>
  </link>
  <joint name="right_hip_pitch_joint" type="revolute">
    <origin xyz="0 -0.064452 -0.1027" rpy="0 0 0"/>
    <parent link="pelvis"/>
    <child link="right_hip_pitch_link"/>
    <axis xyz="0 1 0"/>
    <limit lower="-2.5307" upper="2.8798" effort="88" velocity="32"/>
  </joint>

  <link name="right_hip_roll_link">
    <inertial>
      <origin xyz="0.029812 0.001045 -0.087934" rpy="0 0 0"/>
      <mass value="1.52"/>
      <inertia ixx="0.00254986" ixy="0" ixz="0" iyy="0.00241169" iyz="0" izz="0.00148755"/>
    </inertial>
    <visual>
      <origin xyz="0 0 0" rpy="0 0 0"/>
      <geometry>
        <mesh filename="package://humanoid_legged_description/meshes/right_hip_roll_link.STL"/>
      </geometry>
      <material name="auto">
        <color rgba="0.7 0.7 0.7 1"/>
      </material>
    </visual>
  </link>
  <joint name="right_hip_roll_joint" type="revolute">
    <origin xyz="0 -0.052 -0.030465" rpy="0 -0.1749 0"/>
    <parent link="right_hip_pitch_link"/>
    <child link="right_hip_roll_link"/>
    <axis xyz="1 0 0"/>
    <limit lower="-2.9671" upper="0.5236" effort="88" velocity="32"/>
  </joint>

  <link name="right_hip_yaw_link">
    <inertial>
      <origin xyz="-0.057709 0.010981 -0.15078" rpy="0 0 0"/>
      <mass value="1.702"/>
      <inertia ixx="0.00776166" ixy="0" ixz="0" iyy="0.00717575" iyz="0" izz="0.00160139"/>
    </inertial>
    <visual>
      <origin xyz="0 0 0" rpy="0 0 0"/>
      <geometry>
        <mesh filename="package://humanoid_legged_description/meshes/right_hip_yaw_link.STL"/>
      </geometry>
      <material name="auto">
        <color rgba="0.7 0.7 0.7 1"/>
      </material>
    </visual>
  </link>
  <joint name="right_hip_yaw_joint" type="revolute">
    <origin xyz="0.025001 0 -0.12412" rpy="0 0 0"/>
    <parent link="right_hip_roll_link"/>
    <child link="right_hip_yaw_link"/>
    <axis xyz="0 0 1"/>
    <limit lower="-2.7576" upper="2.7576" effort="88" velocity="32"/>
  </joint>

  <link name="right_knee_link">
    <inertial>
      <origin xyz="0.005457 -0.003964 -0.12074" rpy="0 0 0"/>
      <mass value="1.932"/>
      <inertia ixx="0.011374" ixy="0" ixz="0" iyy="0.0112843" iyz="0" izz="0.00146452"/>
    </inertial>
    <visual>
      <origin xyz="0 0 0" rpy="0 0 0"/>
      <geometry>
        <mesh filename="package://humanoid_legged_description/meshes/right_knee_link.STL"/>
      </geometry>
      <material name="auto">
        <color rgba="0.7 0.7 0.7 1"/>
      </material>
    </visual>
  </link>
  <joint name="right_knee_joint" type="revolute">
    <origin xyz="-0.078273 -0.0021489 -0.17734" rpy="0 0.1749 0"/>
    <parent link="right_hip_yaw_link"/>
    <child link="right_knee_link"/>
    <axis xyz="0 1 0"/>
    <limit lower="-0.087267" upper="2.8798" effort="139" velocity="20"/>
  </joint>

  <link name="right_ankle_pitch_link">
    <inertial>
      <origin xyz="-0.007269 0 0.011137" rpy="0 0 0"/>
      <mass value="0.074"/>
      <inertia ixx="1.89e-05" ixy="0" ixz="0" iyy="1.40805e-05" iyz="0" izz="6.9195e-06"/>
    </inertial>
    <visual>
      <origin xyz="0 0 0" rpy="0 0 0"/>
      <geometry>
        <mesh filename="package://humanoid_legged_description/meshes/right_ankle_pitch_link.STL"/>
      </geometry>
      <material name="auto">
        <color rgba="0.7 0.7 0.7 1"/>
      </material>
    </visual>
  </link>
  <joint name="right_ankle_pitch_joint" type="revolute">
    <origin xyz="0 9.4445e-05 -0.30001" rpy="0 0 0"/>
    <parent link="right_knee_link"/>
    <child link="right_ankle_pitch_link"/>
    <axis xyz="0 1 0"/>
    <limit lower="-0.87267" upper="0.5236" effort="50" velocity="30"/>
  </joint>

  <link name="right_ankle_roll_link">
    <inertial>
      <origin xyz="0.026505 0 -0.016425" rpy="0 0 0"/>
      <mass value="0.608"/>
      <inertia ixx="0.00167218" ixy="0" ixz="0" iyy="0.0016161" iyz="0" izz="0.000217621"/>
    </inertial>
    <visual>
      <origin xyz="0 0 0" rpy="0 0 0"/>
      <geometry>
        <mesh filename="package://humanoid_legged_description/meshes/right_ankle_roll_link.STL"/>
      </geometry>
      <material name="dark_grey">
        <color rgba="0.35 0.35 0.38 1"/>
      </material>
    </visual>
    <collision>
      <origin xyz="0.035 0 -0.03" rpy="0 0 0"/>
      <geometry>
        <box size="0.18 0.08 0.01"/>
      </geometry>
    </collision>
  </link>
  <joint name="right_ankle_roll_joint" type="revolute">
    <origin xyz="0 0 -0.017558" rpy="0 0 0"/>
    <parent link="right_ankle_pitch_link"/>
    <child link="right_ankle_roll_link"/>
    <axis xyz="1 0 0"/>
    <limit lower="-0.2618" upper="0.2618" effort="50" velocity="30"/>
  </joint>

  <!-- Right foot contact frames -->
  <link name="r_foot_toe"></link>
  <joint name="r_foot_toe_joint" type="fixed">
    <origin xyz="0.12 0 -0.03" rpy="0 0 0"/>
    <parent link="right_ankle_roll_link"/>
    <child link="r_foot_toe"/>
  </joint>
  <link name="r_foot_heel"></link>
  <joint name="r_foot_heel_joint" type="fixed">
    <origin xyz="-0.05 0 -0.03" rpy="0 0 0"/>
    <parent link="right_ankle_roll_link"/>
    <child link="r_foot_heel"/>
  </joint>

  <!-- ============== UPPER BODY (all fixed) ============== -->
  <link name="waist_yaw_link">
    <inertial>
      <origin xyz="0.003964 0 0.018769" rpy="0 0 0"/>
      <mass value="0.244"/>
      <inertia ixx="0.000158561" ixy="0" ixz="0" iyy="0.000124229" iyz="0" izz="9.67669e-05"/>
    </inertial>
    <visual>
      <origin xyz="0 0 0" rpy="0 0 0"/>
      <geometry>
        <mesh filename="package://humanoid_legged_description/meshes/waist_yaw_link.STL"/>
      </geometry>
      <material name="auto">
        <color rgba="0.7 0.7 0.7 1"/>
      </material>
    </visual>
  </link>
  <joint name="waist_yaw_joint" type="fixed">
    <origin xyz="0 0 0" rpy="0 0 0"/>
    <parent link="pelvis"/>
    <child link="waist_yaw_link"/>
  </joint>

  <link name="waist_roll_link">
    <inertial>
      <origin xyz="0 -0.000236 0.010111" rpy="0 0 0"/>
      <mass value="0.047"/>
      <inertia ixx="7.515e-06" ixy="0" ixz="0" iyy="6.40206e-06" iyz="0" izz="3.98394e-06"/>
    </inertial>
    <visual>
      <origin xyz="0 0 0" rpy="0 0 0"/>
      <geometry>
        <mesh filename="package://humanoid_legged_description/meshes/waist_roll_link.STL"/>
      </geometry>
      <material name="auto">
        <color rgba="0.7 0.7 0.7 1"/>
      </material>
    </visual>
  </link>
  <joint name="waist_roll_joint" type="fixed">
    <origin xyz="-0.0039635 0 0.035" rpy="0 0 0"/>
    <parent link="waist_yaw_link"/>
    <child link="waist_roll_link"/>
  </joint>

  <link name="torso_link">
    <inertial>
      <origin xyz="0.00331658 0.000261533 0.179856" rpy="0 0 0"/>
      <mass value="9.598"/>
      <inertia ixx="0.12407" ixy="0" ixz="0" iyy="0.111951" iyz="0" izz="0.0325382"/>
    </inertial>
    <visual>
      <origin xyz="0 0 0" rpy="0 0 0"/>
      <geometry>
        <mesh filename="package://humanoid_legged_description/meshes/torso_link.STL"/>
      </geometry>
      <material name="auto">
        <color rgba="0.7 0.7 0.7 1"/>
      </material>
    </visual>
    <collision>
      <origin xyz="0 0 0.15" rpy="0 0 0"/>
      <geometry>
        <box size="0.2 0.3 0.35"/>
      </geometry>
    </collision>
  </link>
  <joint name="waist_pitch_joint" type="fixed">
    <origin xyz="0 0 0.019" rpy="0 0 0"/>
    <parent link="waist_roll_link"/>
    <child link="torso_link"/>
  </joint>

  <link name="head_link">
    <inertial>
      <origin xyz="0 0 0.08" rpy="0 0 0"/>
      <mass value="1.036"/>
      <inertia ixx="0.002" ixy="0" ixz="0" iyy="0.002" iyz="0" izz="0.001"/>
    </inertial>
    <visual>
      <origin xyz="0 0 0" rpy="0 0 0"/>
      <geometry>
        <mesh filename="package://humanoid_legged_description/meshes/head_link.STL"/>
      </geometry>
      <material name="white">
        <color rgba="0.92 0.92 0.92 1"/>
      </material>
    </visual>
  </link>
  <joint name="head_joint" type="fixed">
    <origin xyz="0.0039635 0 -0.044" rpy="0 0 0"/>
    <parent link="torso_link"/>
    <child link="head_link"/>
  </joint>

  <!-- Left arm (all fixed) -->
  <link name="left_shoulder_pitch_link">
    <inertial>
      <origin xyz="0 0.035892 -0.011628" rpy="0 0 0"/>
      <mass value="0.718"/>
      <inertia ixx="0.000465864" ixy="0" ixz="0" iyy="0.000432842" iyz="0" izz="0.000406394"/>
    </inertial>
    <visual>
      <origin xyz="0 0 0" rpy="0 0 0"/>
      <geometry>
        <mesh filename="package://humanoid_legged_description/meshes/left_shoulder_pitch_link.STL"/>
      </geometry>
      <material name="auto">
        <color rgba="0.7 0.7 0.7 1"/>
      </material>
    </visual>
  </link>
  <joint name="left_shoulder_pitch_joint" type="fixed">
    <origin xyz="0.0039563 0.10022 0.24778" rpy="0.27931 0.000054949 -0.00019159"/>
    <parent link="torso_link"/>
    <child link="left_shoulder_pitch_link"/>
  </joint>

  <link name="left_shoulder_roll_link">
    <inertial>
      <origin xyz="-0.000227 0.00727 -0.063243" rpy="0 0 0"/>
      <mass value="0.643"/>
      <inertia ixx="0.000691311" ixy="0" ixz="0" iyy="0.000618011" iyz="0" izz="0.000388977"/>
    </inertial>
    <visual>
      <origin xyz="0 0 0" rpy="0 0 0"/>
      <geometry>
        <mesh filename="package://humanoid_legged_description/meshes/left_shoulder_roll_link.STL"/>
      </geometry>
      <material name="auto">
        <color rgba="0.7 0.7 0.7 1"/>
      </material>
    </visual>
  </link>
  <joint name="left_shoulder_roll_joint" type="fixed">
    <origin xyz="0 0.038 -0.013831" rpy="-0.27925 0 0"/>
    <parent link="left_shoulder_pitch_link"/>
    <child link="left_shoulder_roll_link"/>
  </joint>

  <link name="left_shoulder_yaw_link">
    <inertial>
      <origin xyz="0.010773 -0.002949 -0.072009" rpy="0 0 0"/>
      <mass value="0.734"/>
      <inertia ixx="0.00106187" ixy="0" ixz="0" iyy="0.00103217" iyz="0" izz="0.000400661"/>
    </inertial>
    <visual>
      <origin xyz="0 0 0" rpy="0 0 0"/>
      <geometry>
        <mesh filename="package://humanoid_legged_description/meshes/left_shoulder_yaw_link.STL"/>
      </geometry>
      <material name="auto">
        <color rgba="0.7 0.7 0.7 1"/>
      </material>
    </visual>
  </link>
  <joint name="left_shoulder_yaw_joint" type="fixed">
    <origin xyz="0 0.00624 -0.1032" rpy="0 0 0"/>
    <parent link="left_shoulder_roll_link"/>
    <child link="left_shoulder_yaw_link"/>
  </joint>

  <link name="left_elbow_link">
    <inertial>
      <origin xyz="0.064956 0.004454 -0.010062" rpy="0 0 0"/>
      <mass value="0.6"/>
      <inertia ixx="0.000443035" ixy="0" ixz="0" iyy="0.000421612" iyz="0" izz="0.000259353"/>
    </inertial>
    <visual>
      <origin xyz="0 0 0" rpy="0 0 0"/>
      <geometry>
        <mesh filename="package://humanoid_legged_description/meshes/left_elbow_link.STL"/>
      </geometry>
      <material name="auto">
        <color rgba="0.7 0.7 0.7 1"/>
      </material>
    </visual>
  </link>
  <joint name="left_elbow_joint" type="fixed">
    <origin xyz="0.015783 0 -0.080518" rpy="0 0 0"/>
    <parent link="left_shoulder_yaw_link"/>
    <child link="left_elbow_link"/>
  </joint>

  <link name="left_rubber_hand">
    <inertial>
      <origin xyz="0.05 0 0" rpy="0 0 0"/>
      <mass value="0.824"/>
      <inertia ixx="0.001" ixy="0" ixz="0" iyy="0.001" iyz="0" izz="0.0005"/>
    </inertial>
    <visual>
      <origin xyz="0 0 0" rpy="0 0 0"/>
      <geometry>
        <mesh filename="package://humanoid_legged_description/meshes/left_rubber_hand.STL"/>
      </geometry>
      <material name="dark_rubber">
        <color rgba="0.35 0.35 0.38 1"/>
      </material>
    </visual>
  </link>
  <joint name="left_hand_joint" type="fixed">
    <origin xyz="0.1 0.00188791 -0.01" rpy="0 0 0"/>
    <parent link="left_elbow_link"/>
    <child link="left_rubber_hand"/>
  </joint>

  <!-- Right arm (all fixed) -->
  <link name="right_shoulder_pitch_link">
    <inertial>
      <origin xyz="0 -0.035892 -0.011628" rpy="0 0 0"/>
      <mass value="0.718"/>
      <inertia ixx="0.000465864" ixy="0" ixz="0" iyy="0.000432842" iyz="0" izz="0.000406394"/>
    </inertial>
    <visual>
      <origin xyz="0 0 0" rpy="0 0 0"/>
      <geometry>
        <mesh filename="package://humanoid_legged_description/meshes/right_shoulder_pitch_link.STL"/>
      </geometry>
      <material name="auto">
        <color rgba="0.7 0.7 0.7 1"/>
      </material>
    </visual>
  </link>
  <joint name="right_shoulder_pitch_joint" type="fixed">
    <origin xyz="0.0039563 -0.10021 0.24778" rpy="-0.27931 0.000054949 0.00019159"/>
    <parent link="torso_link"/>
    <child link="right_shoulder_pitch_link"/>
  </joint>

  <link name="right_shoulder_roll_link">
    <inertial>
      <origin xyz="-0.000227 -0.00727 -0.063243" rpy="0 0 0"/>
      <mass value="0.643"/>
      <inertia ixx="0.000691311" ixy="0" ixz="0" iyy="0.000618011" iyz="0" izz="0.000388977"/>
    </inertial>
    <visual>
      <origin xyz="0 0 0" rpy="0 0 0"/>
      <geometry>
        <mesh filename="package://humanoid_legged_description/meshes/right_shoulder_roll_link.STL"/>
      </geometry>
      <material name="auto">
        <color rgba="0.7 0.7 0.7 1"/>
      </material>
    </visual>
  </link>
  <joint name="right_shoulder_roll_joint" type="fixed">
    <origin xyz="0 -0.038 -0.013831" rpy="0.27925 0 0"/>
    <parent link="right_shoulder_pitch_link"/>
    <child link="right_shoulder_roll_link"/>
  </joint>

  <link name="right_shoulder_yaw_link">
    <inertial>
      <origin xyz="0.010773 0.002949 -0.072009" rpy="0 0 0"/>
      <mass value="0.734"/>
      <inertia ixx="0.00106187" ixy="0" ixz="0" iyy="0.00103217" iyz="0" izz="0.000400661"/>
    </inertial>
    <visual>
      <origin xyz="0 0 0" rpy="0 0 0"/>
      <geometry>
        <mesh filename="package://humanoid_legged_description/meshes/right_shoulder_yaw_link.STL"/>
      </geometry>
      <material name="auto">
        <color rgba="0.7 0.7 0.7 1"/>
      </material>
    </visual>
  </link>
  <joint name="right_shoulder_yaw_joint" type="fixed">
    <origin xyz="0 -0.00624 -0.1032" rpy="0 0 0"/>
    <parent link="right_shoulder_roll_link"/>
    <child link="right_shoulder_yaw_link"/>
  </joint>

  <link name="right_elbow_link">
    <inertial>
      <origin xyz="0.064956 -0.004454 -0.010062" rpy="0 0 0"/>
      <mass value="0.6"/>
      <inertia ixx="0.000443035" ixy="0" ixz="0" iyy="0.000421612" iyz="0" izz="0.000259353"/>
    </inertial>
    <visual>
      <origin xyz="0 0 0" rpy="0 0 0"/>
      <geometry>
        <mesh filename="package://humanoid_legged_description/meshes/right_elbow_link.STL"/>
      </geometry>
      <material name="auto">
        <color rgba="0.7 0.7 0.7 1"/>
      </material>
    </visual>
  </link>
  <joint name="right_elbow_joint" type="fixed">
    <origin xyz="0.015783 0 -0.080518" rpy="0 0 0"/>
    <parent link="right_shoulder_yaw_link"/>
    <child link="right_elbow_link"/>
  </joint>

  <link name="right_rubber_hand">
    <inertial>
      <origin xyz="0.05 0 0" rpy="0 0 0"/>
      <mass value="0.824"/>
      <inertia ixx="0.001" ixy="0" ixz="0" iyy="0.001" iyz="0" izz="0.0005"/>
    </inertial>
    <visual>
      <origin xyz="0 0 0" rpy="0 0 0"/>
      <geometry>
        <mesh filename="package://humanoid_legged_description/meshes/right_rubber_hand.STL"/>
      </geometry>
      <material name="dark_rubber">
        <color rgba="0.35 0.35 0.38 1"/>
      </material>
    </visual>
  </link>
  <joint name="right_hand_joint" type="fixed">
    <origin xyz="0.1 -0.00188791 -0.01" rpy="0 0 0"/>
    <parent link="right_elbow_link"/>
    <child link="right_rubber_hand"/>
  </joint>

</robot>
